<mujoco model="rat">
  <compiler angle="radian"/>

  <size njmax="8000" nconmax="4000"/>

  <visual>
    <quality shadowsize="2048"/>
    <global offheight="2200" offwidth="3208"/>
  </visual>

  <default>
    <joint limited="true" solreflimit="0.01 1" solimplimit="0.99 0.9999 0" armature="6e-07" damping="0.001"/>
    <geom friction="0.7 0.005 0.0001" solref="0.005 1"/>
    <site group="3" rgba="0 0 1 1"/>
    <tendon limited="false"/>
    <general ctrllimited="true" forcelimited="false" dyntype="filter" biastype="affine" dynprm="0.04"/>
    <default class="bone">
      <geom contype="0" conaffinity="0" group="0" rgba="0.5 0.5 0.5 1" density="1100"/>
    </default>
    <default class="collision">
      <geom contype="1" conaffinity="1" condim="1" group="2"/>
      <default class="collision_primitive">
        <geom type="capsule" group="2" rgba="0 0.5 0.5 1" density="500"/>
        <default class="collision_primitive_paw">
          <geom condim="3" priority="1" rgba="0 0.6 0.7 1" friction="1.5 0.005 0.0001"/>
        </default>
        <default class="nonself_collision_primitive">
          <geom conaffinity="0"/>
        </default>
      </default>
    </default>
    <default class="lumbar">
      <joint group="3" pos="0.003 0 -0.003" armature="1e-05" damping="0.03"/>
      <general forcerange="-20 20" gainprm="20" biasprm="0 -20"/>
      <default class="lumbar_extend">
        <joint stiffness="0.02" range="-0.5236 0.7854"/>
        <tendon range="-1 1"/>
        <general ctrlrange="-0.5236 0.7854"/>
      </default>
      <default class="lumbar_bend">
        <joint stiffness="0.03" range="-0.5236 0.5236"/>
        <tendon range="-1 1"/>
        <general ctrlrange="-0.5236 0.5236"/>
      </default>
      <default class="lumbar_twist">
        <joint stiffness="0.03" range="-0.5236 0.5236"/>
        <tendon range="-1 1"/>
        <general ctrlrange="-0.5236 0.5236"/>
      </default>
    </default>
    <default class="cervical">
      <joint group="3" pos="-0.02 0 -0.05" stiffness="1" armature="0.001" damping="1"/>
      <general forcerange="-20 20" gainprm="20" biasprm="0 -20"/>
      <default class="cervical_extend">
        <joint range="-0.40724 0.61087"/>
        <tendon range="-1 1"/>
        <general ctrlrange="-0.40724 0.61087"/>
      </default>
      <default class="cervical_bend">
        <joint range="-0.61087 0.61087"/>
        <tendon range="-1 1"/>
        <general ctrlrange="-0.61087 0.61087"/>
      </default>
      <default class="cervical_twist">
        <joint range="-0.61087 0.61087"/>
        <tendon range="-1 1"/>
        <general ctrlrange="-0.61087 0.61087"/>
      </default>
    </default>
    <default class="atlas">
      <joint axis="0 -1 0" stiffness="0.002" range="-0.087266 0.7854" damping="0.002"/>
      <general ctrlrange="-0.087266 0.7854" forcerange="-0.025 0.025" gainprm="0.05" biasprm="0 -0.05"/>
    </default>
    <default class="mandible">
      <joint stiffness="0.002" range="-0.29671 0.2618" springref="-0.31416" damping="0.002"/>
      <general ctrlrange="-0.29671 0.2618" forcerange="-0.025 0.025" gainprm="0.05" biasprm="0 -0.05"/>
    </default>
    <default class="caudal">
      <joint group="3" stiffness="1e-05" damping="0.002"/>
      <general forcerange="-0.1 0.1" gainprm="0.1" biasprm="0 -0.1"/>
      <default class="caudal_extend">
        <joint range="-0.087266 0.087266"/>
        <tendon range="-0.05 0.05"/>
        <general ctrlrange="-0.2618 0.2618"/>
      </default>
      <default class="caudal_bend">
        <joint range="-0.087266 0.087266"/>
        <tendon range="-0.2 0.2"/>
        <general ctrlrange="-0.2618 0.2618"/>
      </default>
    </default>
    <default class="hip">
      <joint armature="1e-05" damping="0.02"/>
      <general gainprm="0.2"/>
      <default class="hip_supinate">
        <joint range="-0.69813 0.5236"/>
        <general ctrlrange="-0.69813 0.5236" forcerange="-0.2 0.2" gainprm="0.4" biasprm="0 -0.4"/>
      </default>
      <default class="hip_abduct">
        <joint range="-0.5236 1.0472"/>
        <general ctrlrange="-0.5236 1.0472" forcerange="-0.2 0.2" gainprm="0.4" biasprm="0 -0.4"/>
      </default>
      <default class="hip_extend">
        <joint range="-1.5708 1.0472"/>
        <general ctrlrange="-1.5708 1.0472" forcerange="-0.3 0.3" gainprm="0.6" biasprm="0 -0.6"/>
      </default>
    </default>
    <default class="knee">
      <joint range="-1.2217 1.5359" damping="0.005"/>
      <general ctrlrange="-1.2217 1.5359" forcerange="-0.2 0.2" gainprm="0.4" biasprm="0 -0.4"/>
    </default>
    <default class="ankle">
      <joint range="-0.13963 1.3963" damping="0.003"/>
      <general ctrlrange="-0.13963 1.3963" forcerange="-0.2 0.2" gainprm="0.4" biasprm="0 -0.4"/>
    </default>
    <default class="toe">
      <joint range="-0.7854 1.5708" damping="0.001"/>
      <general ctrlrange="-0.7854 1.5708" forcerange="-0.025 0.025" gainprm="0.05" biasprm="0 -0.05"/>
    </default>
    <default class="scapula">
      <joint damping="0.005"/>
      <general forcerange="-0.25 0.25" gainprm="0.5" biasprm="0 -0.5"/>
      <default class="scapula_supinate">
        <joint pos="0 0.005 0" range="-0.017453 0.17453"/>
        <general ctrlrange="-0.017453 0.17453"/>
      </default>
      <default class="scapula_abduct">
        <joint pos="0 0.005 -0.01" range="-0.2618 0.2618"/>
        <general ctrlrange="-0.2618 0.2618"/>
      </default>
      <default class="scapula_extend">
        <joint pos="0 0 0" range="-0.034907 0.034907"/>
        <general ctrlrange="-0.034907 0.034907"/>
      </default>
    </default>
    <default class="shoulder">
      <joint range="-1.309 0.87266" damping="0.005"/>
      <general ctrlrange="-1.309 0.87266" forcerange="-0.15 0.15" gainprm="0.3" biasprm="0 -0.3"/>
    </default>
    <default class="shoulder_sup">
      <joint range="-0.05236 1.1345" damping="0.005"/>
      <general ctrlrange="-0.05236 1.1345" forcerange="-0.15 0.15" gainprm="0.3" biasprm="0 -0.3"/>
    </default>
    <default class="elbow">
      <joint range="-1.309 0.69813" damping="0.003"/>
      <general ctrlrange="-1.309 0.69813" forcerange="-0.15 0.15" gainprm="0.3" biasprm="0 -0.3"/>
    </default>
    <default class="wrist">
      <joint range="-0.34907 2.0944" damping="0.002"/>
      <general ctrlrange="-0.34907 2.0944" forcerange="-0.05 0.05" gainprm="0.1" biasprm="0 -0.1"/>
    </default>
    <default class="finger">
      <joint range="0 1.5708" damping="0.002"/>
      <general ctrlrange="0 1.5708" forcerange="-0.025 0.025" gainprm="0.05" biasprm="0 -0.05"/>
    </default>
    <default class="sensor">
      <site group="4"/>
    </default>
  </default>

  <statistic meansize="0.003"/>



  <worldbody>

    <camera name="Cam13" mode="fixed" focalpixel="2477.229548414393 2477.229548414393" resolution="3208 2200" sensorsize="0.014436 0.0099" pos="-0.7601674022374256 -1.437212204600267 0.8074461972683981" xyaxes="0.84311395 -0.53753789 0.01455625 0.20435236 0.34532512 0.91596434"/>




    <camera name="Cam14"  mode="fixed" pos="0 -2 0.412"  xyaxes="1 0 0.000 0 0.256 1"/>






    <body name="torso" pos="0.030995 2.0585e-07 0.06509">
      <site name="neck_3_kpsite" type="sphere" size=".005 .005 .005" rgba=".9 .6 .7 1" pos="0.025 0 0.02"/>






      <light name="tracking_light" mode="trackcom" pos="0 0 3"/>
      <camera name="back" mode="trackcom" pos="-1 0 0.5" xyaxes="0 -1 0 1 0 2"/>
      <camera name="side" mode="trackcom" pos="0 -1 0.5" xyaxes="1 0 0 0 1 2"/>
      <camera name="side_alt" mode="trackcom" pos="0.5 -0.561 0.199" xyaxes="0.766 0.643 0 -0.162 0.192 0.968"/>
      <camera name="side_alt2" mode="trackcom" pos="-0.386 -2.103 1.099" xyaxes="0.986 -0.164 -0.000 0.072 0.435 0.898"/>

       <camera name="faroff" mode="trackcom"  pos="-0.129 -4.905 1.394" xyaxes="1.000 -0.019 0.000 0.005 0.264 0.965"/>
       <camera/>


      

      <geom name="collision_torso" class="nonself_collision_primitive" type="ellipsoid" size="0.05 0.024 0.026" density="468.25" pos="-0.0082 0 0" euler="0 0.17453 0"/>
      <body name="vertebra_1" pos="-0.019179 -1.8803e-07 0.016846">
        <geom name="vertebra_1_collision" class="nonself_collision_primitive" type="sphere" size="0.01" pos="0 0 -0.00164"/>
        <body name="vertebra_2" pos="-0.0056297 2.5948e-06 0.00053209">
          <geom name="vertebra_2_collision" class="nonself_collision_primitive" type="sphere" size="0.01" pos="0 0 -0.00164"/>
          <body name="vertebra_3" pos="-0.0065172 -1.0411e-05 -9.4672e-05">
            <geom name="vertebra_3_collision" class="nonself_collision_primitive" type="sphere" size="0.01" pos="0 0 -0.00164"/>
            <body name="vertebra_4" pos="-0.0067777 8.7461e-06 -0.0012993">
              <geom name="vertebra_4_collision" class="nonself_collision_primitive" type="sphere" size="0.01" pos="0 0 -0.00164"/>
              <body name="vertebra_5" pos="-0.0068901 -6.2043e-06 -0.0024981">

                <site name="spineL_4_kpsite" type="sphere" size=".005 .005 .005" rgba=".9 .6 .7 1" pos="0 0 0.007"/>

                <geom name="vertebra_5_collision" class="nonself_collision_primitive" type="sphere" size="0.01" pos="0 0 -0.00164"/>
                <body name="vertebra_6" pos="-0.0061853 5.2544e-06 -0.0036411">
                  <geom name="vertebra_6_collision" class="nonself_collision_primitive" type="sphere" size="0.01" pos="0 0 -0.00164"/>
                  <joint name="vertebra_6_twist" class="lumbar_twist" axis="1 0 0"/>
                  <body name="pelvis" pos="-0.013071 3.5132e-06 -0.008121">
                    <geom name="collision_pelvis_L" class="nonself_collision_primitive" size="0.013 0.021 0" density="1548.6" pos="-0.00082 0.00656 -0.00574" euler="0 0.87266 0"/>
                    <geom name="collision_pelvis_R" class="nonself_collision_primitive" size="0.013 0.021 0" density="1548.6" pos="-0.00082 -0.00656 -0.00574" euler="0 0.87266 0"/>
                    <geom name="collision_pelvis_gut" class="nonself_collision_primitive" type="ellipsoid" size="0.02 0.02 0.018" density="1548.6" pos="0.0205 0 -0.0164" euler="0 -0.5236 0"/>
                    <site name="hip_L" size="0.0022" pos="-0.0048103 0.011491 -0.0098878"/>
                    <site name="hip_R" size="0.0022" pos="-0.0048103 -0.011491 -0.0098878"/>
                    
                    <body name="upper_leg_L" pos="-0.0048103 0.011491 -0.0098878">
                      <joint name="hip_L_supinate" class="hip_supinate" axis="0 0 1"/>
                      <joint name="hip_L_abduct" class="hip_abduct" axis="1 0 0"/>
                      <joint name="hip_L_extend" class="hip_extend" axis="0 1 0"/>
                      <site name="knee_L" type="cylinder" size="0.0006 0.004" pos="0.015423 0.017479 -0.025704" zaxis="0 1 0"/>
                      <geom name="upper_leg_L0_collision" class="collision_primitive" size="0.0087424 0.017485" density="1561.8" pos="0.0086025 0.010753 -0.012904" euler="0.61087 -0.69813 0"/>
                      

                    <body name="lower_leg_L" pos="0.01542264534586861 0.01747899805865108 -0.02570440890978101">

                        <site name="knee_L_14_kpsite" type="sphere" size=".01 .01 .01" rgba=".9 .6 .7 1" pos="0 0 0"/>

                        <joint name="knee_L" class="knee" axis="0.5 -1 0"/>
                        <site name="ankle_L" type="cylinder" size="0.0006000000000000001 0.0026" pos="-0.03230154033783406 -0.004727054683585472 -0.02205958852339887" zaxis="0 1 0"/>
                        <body name="foot_L" pos="-0.03230154033783406 -0.004727054683585472 -0.02205958852339887">

                          <site name="ankle_L_15_kpsite" type="sphere" size=".008 .008 .008" rgba=".9 .6 .7 1" pos="0 0 0"/>

                          <joint name="ankle_L" class="ankle" axis="-0.3 1 0"/>
                          <geom name="foot_L_collision" class="collision_primitive_paw" size="0.005210712207833968 0.01238417565878816" density="2041.15978228" pos="0.008274464032760684 0.002256672008934731 -0.002256672008934731" euler="1.570796326794897 -1.221730476396031 0"/>
                          <site name="toe_L" type="cylinder" size="0.0006000000000000001 0.005000000000000001" pos="0.02109994311367263 0.007614327297542731 -0.002752166493087734" zaxis="0 1 0"/>
                          <body name="toe_L" pos="0.02109994311367263 0.007614327297542731 -0.002752166493087734">

                            <site name="foot_L_16_kpsite" type="sphere" size=".005 .005 .005" rgba=".9 .6 .7 1" pos="0 0 0"/>

                            <site name="sole_L" class="sensor" type="box" size="0.006 0.004 0.002" pos="0.008200000000000001 0.00246 -0.00164" euler="0 0 0.3490658503988659"/>
                          </body>
                        </body>
                        <geom name="lower_leg_L_collision" class="collision_primitive" size="0.006556802251673236 0.01923328660490816" density="1302.86687267" pos="-0.01226339046929431 0.0001224792426221771 -0.01071813365303941" quat="0.5843939876140521 0.278581552273902 0.3900453953818352 0.6547828460754284"/>
                      </body>
                    </body>
               



                    <body name="upper_leg_R" pos="-0.0048103 -0.011491 -0.0098878">
                      <joint name="hip_R_supinate" class="hip_supinate" axis="0 0 -1"/>
                      <joint name="hip_R_abduct" class="hip_abduct" axis="-1 0 0"/>
                      <joint name="hip_R_extend" class="hip_extend" axis="0 1 0"/>
                      <site name="knee_R" type="cylinder" size="0.0006 0.004" pos="0.015423 -0.017479 -0.025704" zaxis="0 1 0"/>
                      <geom name="upper_leg_R0_collision" class="collision_primitive" size="0.0087424 0.017485" density="1561.8" pos="0.0086025 -0.010753 -0.012904" euler="-0.61087 -0.69813 0"/>
                     
                     
                     
                     
                      <body name="lower_leg_R" pos="0.01542264534586861 -0.01747899805865108 -0.02570440890978101">

                        <site name="knee_R_17_kpsite" type="sphere" size=".01 .01 .01" rgba=".9 .6 .7 1" pos="0 0 0"/>

                        <joint name="knee_R" class="knee" axis="-0.5 -1 0"/>
                        <site name="ankle_R" type="cylinder" size="0.0006000000000000001 0.0026" pos="-0.03230154033783406 0.004727054683585472 -0.02205958852339887" zaxis="0 1 0"/>
                        <body name="foot_R" pos="-0.03230154033783406 0.004727054683585472 -0.02205958852339887">

                          <site name="ankle_R_18_kpsite" type="sphere" size=".008 .008 .008" rgba=".9 .6 .7 1" pos="0 0 0"/>

                          <joint name="ankle_R" class="ankle" axis="0.3 1 0"/>
                          <geom name="foot_R_collision" class="collision_primitive_paw" size="0.005210712207833968 0.01238417565878816" density="2041.15978228" pos="0.008274464032760684 -0.002256672008934731 -0.002256672008934731" euler="1.570796326794897 1.221730476396031 0"/>
                          <site name="toe_R" type="cylinder" size="0.0006000000000000001 0.005000000000000001" pos="0.02109994311367263 -0.007614327297542731 -0.002752166493087734" zaxis="0 1 0"/>
                          <body name="toe_R" pos="0.02109994311367263 -0.007614327297542731 -0.002752166493087734">

                            <site name="foot_R_19_kpsite" type="sphere" size=".005 .005 .005" rgba=".9 .6 .7 1" pos="0 0 0"/>

                  
                            <site name="sole_R" class="sensor" type="box" size="0.006 0.004 0.002" pos="0.008200000000000001 -0.00246 -0.00164" euler="0 0 -0.3490658503988659"/>
                          </body>
                        </body>
                        <geom name="lower_leg_R_collision" class="collision_primitive" size="0.006556802251673236 0.01923328660490816" density="1302.86687267" pos="-0.01202896613332032 -0.0001615786954038913 -0.0105741369075766" quat="0.6564315036111004 0.3901417719765998 0.2779576926818845 0.5827749135856758"/>
                      </body>
                    </body>
                   
                   
                   
                   
                   
                    <body name="vertebra_C1" pos="-0.01579 0 -0.011882">
                      <body name="vertebra_C2" pos="-0.0038771 0 -0.0042264">
                        <body name="vertebra_C3" pos="-0.003424 0 -0.0042631">
                          <body name="vertebra_C4" pos="-0.0032719 0 -0.0044168">

                          <site name="tailbase_5_kpsite" type="sphere" size=".005 .005 .005" rgba=".9 .6 .7 1" pos="0 0 0.011"/>



                            <body name="vertebra_C5" pos="-0.003176 0 -0.0045693">
                              <body name="vertebra_C6" pos="-0.0031192 0 -0.0049014">
                                <body name="vertebra_C7" pos="-0.0032158 0 -0.0056444">
                                  <body name="vertebra_C8" pos="-0.0034459 0 -0.0055182">
                                    <body name="vertebra_C9" pos="-0.0042852 0 -0.005115">
                                      <body name="vertebra_C10" pos="-0.0048615 0 -0.0045622">
                                        <body name="vertebra_C11" pos="-0.0053748 0 -0.0043642">
                                          <body name="vertebra_C12" pos="-0.0061345 0 -0.0038415">
                                            <body name="vertebra_C13" pos="-0.0068974 0 -0.0025924">
                                              <body name="vertebra_C14" pos="-0.006825 0 -0.0009089">
                                                <body name="vertebra_C15" pos="-0.0065262 0 -0.00031533">
                                                  <body name="vertebra_C16" pos="-0.0066939 0 -0.00013849">
                                                    <body name="vertebra_C17" pos="-0.0064854 0 -1.6705e-05">
                                                      <body name="vertebra_C18" pos="-0.0062074 0 0">
                                                        <body name="vertebra_C19" pos="-0.0062043 0 0">
                                                          <body name="vertebra_C20" pos="-0.0062284 0 2.5165e-06">
                                                            <body name="vertebra_C21" pos="-0.0061177 0 -0.00010966">
                                                            <body name="vertebra_C22" pos="-0.0065081 0 -1.312e-05">
                                                            <body name="vertebra_C23" pos="-0.0063908 0 0">
                                                            <body name="vertebra_C24" pos="-0.0061807 0 0">
                                                            <body name="vertebra_C25" pos="-0.0059682 0 0">
                                                            <body name="vertebra_C26" pos="-0.0056287 0 0">
                                                            <body name="vertebra_C27" pos="-0.0051931 0 0">
                                                            <body name="vertebra_C28" pos="-0.0050362 0 5.074e-07">
                                                            <body name="vertebra_C29" pos="-0.0047739 0 0">
                                                            <body name="vertebra_C30" pos="-0.0040054 0 -4.1972e-07">
                                                            <geom name="vertebra_C30_collision" class="collision_primitive" size="0.0012979 0.0061625 0.0034565" density="507.16" pos="0 0 0" quat="0 0.70711 0 0.70711"/>
                                                            </body>
                                                            <joint name="vertebra_C29_bend" class="caudal_bend" pos="0.0037408 0 0" axis="0 0 -1" range="-0.2618 0.2618"/>
                                                            <geom name="vertebra_C29_collision" class="collision_primitive" size="0.0012968 0.0059638 0.0026188" density="507.16" pos="0 0 0" quat="0 0.70711 0 0.70711"/>
                                                            </body>
                                                            <geom name="vertebra_C28_collision" class="collision_primitive" size="0.0012968 0.0057649 0.0028778" density="507.16" pos="0 0 0" quat="0 0.70711 0 0.70711"/>
                                                            </body>
                                                            <joint name="vertebra_C27_extend" class="caudal_extend" pos="0.0038538 0 0" axis="0 1 0" range="-0.2618 0.2618"/>
                                                            <geom name="vertebra_C27_collision" class="collision_primitive" size="0.0013796 0.0055662 0.0030614" density="507.16" pos="0 0 0" quat="0 0.70711 0 0.70711"/>
                                                            </body>
                                                            <geom name="vertebra_C26_collision" class="collision_primitive" size="0.0013796 0.0053673 0.0030614" density="507.16" pos="0 0 0" quat="0 0.70711 0 0.70711"/>
                                                            </body>
                                                            <joint name="vertebra_C25_bend" class="caudal_bend" pos="0.0035962 0 0" axis="0 0 -1" range="-0.2618 0.2618"/>
                                                            <geom name="vertebra_C25_collision" class="collision_primitive" size="0.0013796 0.0051686 0.0034789" density="507.16" pos="0 0 0" quat="0 0.70711 0 0.70711"/>
                                                            </body>
                                                            <geom name="vertebra_C24_collision" class="collision_primitive" size="0.0013796 0.0049698 0.0034789" density="507.16" pos="0 0 0" quat="0 0.70711 0 0.70711"/>
                                                            </body>
                                                            <joint name="vertebra_C23_extend" class="caudal_extend" pos="0.0035962 0 0" axis="0 1 0" range="-0.2618 0.2618"/>
                                                            <geom name="vertebra_C23_collision" class="collision_primitive" size="0.0013796 0.004771 0.0037408" density="507.16" pos="0 0 0" quat="0 0.70711 0 0.70711"/>
                                                            </body>
                                                            <geom name="vertebra_C22_collision" class="collision_primitive" size="0.0013796 0.0045722 0.0037408" density="507.16" pos="0 0 0" quat="0 0.70711 0 0.70711"/>
                                                            </body>
                                                            <joint name="vertebra_C21_bend" class="caudal_bend" pos="0.0038632 0 6.925e-05" axis="0.017923 0 -0.99984" range="-0.2618 0.2618"/>
                                                            <geom name="vertebra_C21_collision" class="collision_primitive" size="0.0015305 0.0049721 0.0038538" density="507.16" pos="0 0 0" quat="0 0.70711 0 0.70711"/>
                                                            </body>
                                                            <geom name="vertebra_C20_collision" class="collision_primitive" size="0.0014983 0.0051765 0.0035962" density="507.16" pos="0 0 0" quat="0 0.70711 0 0.70711"/>
                                                          </body>
                                                          <joint name="vertebra_C19_extend" class="caudal_extend" pos="0.0042786 0 0" axis="0 1 0" range="-0.2618 0.2618"/>
                                                          <geom name="vertebra_C19_collision" class="collision_primitive" size="0.001634 0.0051714 0.0035962" density="507.16" pos="0 0 0" quat="0 0.70711 0 0.70711"/>
                                                        </body>
                                                        <geom name="vertebra_C18_collision" class="collision_primitive" size="0.001634 0.0049128 0.0035962" density="507.16" pos="0 0 0" quat="0 0.70711 0 0.70711"/>
                                                      </body>
                                                      <joint name="vertebra_C17_bend" class="caudal_bend" pos="0.0042794 0 1.1023e-05" axis="0.0025757 0 -1" range="-0.2618 0.2618"/>
                                                      <geom name="vertebra_C17_collision" class="collision_primitive" size="0.001634 0.0046542 0.0035962" density="507.16" pos="0 0 0" quat="0 0.70711 0 0.70711"/>
                                                    </body>
                                                    <geom name="vertebra_C16_collision" class="collision_primitive" size="0.0018781 0.0043956 0.0038669" density="507.16" pos="0 0 0" quat="0 0.70711 0 0.70711"/>
                                                  </body>
                                                  <joint name="vertebra_C15_extend" class="caudal_extend" pos="0.0039328 0 0.00019003" axis="0 1 0" range="-0.2618 0.2618"/>
                                                  <geom name="vertebra_C15_collision" class="collision_primitive" size="0.0018453 0.0041371 0.0038638" density="507.16" pos="0 0 0" quat="0 0.69918 0 0.71494"/>
                                                </body>
                                                <geom name="vertebra_C14_collision" class="collision_primitive" size="0.0018451 0.0038785 0.0038637" density="507.16" pos="0 0 0" quat="0 0.68661 0 0.72702"/>
                                              </body>
                                              <joint name="vertebra_C13_bend" class="caudal_bend" pos="0.0035122 0 0.0013201" axis="0.35182 0 -0.93607" range="-0.2618 0.2618"/>
                                              <geom name="vertebra_C13_collision" class="collision_primitive" size="0.0020907 0.00396 0.0042786" density="507.16" pos="0 0 0" quat="0 0.62939 0 0.77709"/>
                                            </body>
                                            <geom name="vertebra_C12_collision" class="collision_primitive" size="0.0024335 0.0041462 0.0042791" density="507.16" pos="0 0 0" quat="0 0.50808 0 0.86131"/>
                                          </body>
                                          <joint name="vertebra_C11_extend" class="caudal_extend" pos="0.002737 0 0.0022224" axis="0 1 0" range="-0.2618 0.2618"/>
                                          <geom name="vertebra_C11_collision" class="collision_primitive" size="0.0024997 0.0038969 0.0042794" density="507.16" pos="0 0 0" quat="0 0.43494 0 0.90046"/>
                                        </body>
                                        <geom name="vertebra_C10_collision" class="collision_primitive" size="0.0034212 0.0051968 0.0039379" density="507.16" pos="0 0 0" quat="0 0.40482 0 0.9144"/>
                                      </body>
                                      <joint name="vertebra_C9_bend" class="caudal_bend" pos="0.0028865 0 0.0034454" axis="0.76655 0 -0.64219" range="-0.2618 0.2618"/>
                                      <geom name="vertebra_C9_collision" class="collision_primitive" size="0.0031306 0.0044949 0.0039374" density="507.16" pos="0 0 0" quat="0.93394 0 0.35744 0"/>
                                    </body>
                                    <geom name="vertebra_C8_collision" class="collision_primitive" size="0.0030158 0.003957 0.0039369" density="507.16" pos="0 0 0" quat="0.95576 0 0.29416 0"/>
                                  </body>
                                  <joint name="vertebra_C7_extend" class="caudal_extend" pos="0.0026902 0 0.0047218" axis="0 1 0" range="-0.2618 0.2618"/>
                                  <geom name="vertebra_C7_collision" class="collision_primitive" size="0.0032569 0.0046389 0.0037521" density="507.16" pos="0 0 0" quat="-0.95872 -0.028644 -0.26293 0.10445"/>
                                </body>
                                <joint name="vertebra_C6_extend" class="caudal_extend" pos="0.0021034 0 0.0033051" axis="0 1 0" range="-0.2618 0.2618"/>
                                <joint name="vertebra_C6_bend" class="caudal_bend" pos="0.0021034 0 0.0033051" axis="0.84365 0 -0.53689" range="-0.2618 0.2618"/>
                                <geom name="vertebra_C6_collision" class="collision_primitive" size="0.0038491 0.0044418 0.0039176" density="507.16" pos="0 0 0" quat="-0.96847 -0.020165 -0.23384 0.083519"/>
                              </body>
                              <joint name="vertebra_C5_extend" class="caudal_extend" pos="0.0020122 0 0.0028951" axis="0 1 0" range="-0.2618 0.2618"/>
                              <joint name="vertebra_C5_bend" class="caudal_bend" pos="0.0020122 0 0.0028951" axis="0.82113 0 -0.57074" range="-0.2618 0.2618"/>
                              <geom name="vertebra_C5_collision" class="collision_primitive" size="0.0045453 0.0037766 0.0035257" density="507.16" pos="0 0 0" quat="0.95956 0 0.28152 0"/>
                            </body>
                            <joint name="vertebra_C4_extend" class="caudal_extend" pos="0.0025361 0 0.0034235" axis="0 1 0" range="-0.2618 0.2618"/>
                            <joint name="vertebra_C4_bend" class="caudal_bend" pos="0.0025361 0 0.0034235" axis="0.80354 0 -0.59524" range="-0.2618 0.2618"/>
                            <geom name="vertebra_C4_collision" class="collision_primitive" size="0.0066528 0.0038517 0.0042605" density="507.16" pos="0 0 0" quat="0.6699 0.22636 0.22636 0.6699"/>
                          </body>
                          <joint name="vertebra_C3_extend" class="caudal_extend" pos="0.0028146 0 0.0035044" axis="0 1 0" range="-0.2618 0.2618"/>
                          <joint name="vertebra_C3_bend" class="caudal_bend" pos="0.0028146 0 0.0035044" axis="0.77966 0 -0.62621" range="-0.2618 0.2618"/>
                          <geom name="vertebra_C3_collision" class="collision_primitive" size="0.007896 0.0040974 0.0044947" density="507.16" pos="0 0 0" quat="0.65841 0.25786 0.25786 0.65841"/>
                        </body>
                        <joint name="vertebra_C2_extend" class="caudal_extend" pos="0.0035585 0 0.0038792" axis="0 1 0" range="-0.2618 0.2618"/>
                        <joint name="vertebra_C2_bend" class="caudal_bend" pos="0.0035585 0 0.0038792" axis="0.73691 0 -0.67599" range="-0.2618 0.2618"/>
                        <geom name="vertebra_C2_collision" class="collision_primitive" size="0.0083604 0.0035062 0.0052642" density="507.16" pos="0 0 0" quat="0.61659 0.34614 0.34614 0.61659"/>
                      </body>
                      <joint name="vertebra_C1_extend" class="caudal_extend" pos="0.0043423 0 0.0032675" axis="0 1 0" range="-0.2618 0.2618"/>
                      <joint name="vertebra_C1_bend" class="caudal_bend" pos="0.0043423 0 0.0032675" axis="0.60127 0 -0.79905" range="-0.2618 0.2618"/>
                      <geom name="vertebra_C1_collision" class="collision_primitive" size="0.010965 0.0023704 0.0054344" density="507.16" pos="0 0 0" quat="0.57724 0.35066 0.32403 0.66245"/>
                    </body>
                  </body>
                </body>
                <joint name="vertebra_5_bend" class="lumbar_bend" axis="0 0 1"/>
              </body>
              <joint name="vertebra_4_extend" class="lumbar_extend" axis="0 1 0"/>
            </body>
            <joint name="vertebra_3_twist" class="lumbar_twist" axis="1 0 0"/>
          </body>
          <joint name="vertebra_2_bend" class="lumbar_bend" axis="0 0 1"/>
        </body>
        <joint name="vertebra_1_extend" class="lumbar_extend" axis="0 1 0"/>
      </body>
      <body name="vertebra_cervical_5" pos="0.027709 1.1826e-05 -0.0010003">
        <geom name="vertebra_cervical_5_collision" class="nonself_collision_primitive" type="sphere" size="0.009" density="300"/>
        <body name="vertebra_cervical_4" pos="0.002409 -1.2015e-05 0.00080958">
          <geom name="vertebra_cervical_4_collision" class="nonself_collision_primitive" type="sphere" size="0.0084" density="300"/>
          <body name="vertebra_cervical_3" pos="0.0021503 0 0.00094153">
            <geom name="vertebra_cervical_3_collision" class="nonself_collision_primitive" type="sphere" size="0.0078" density="300"/>
            <body name="vertebra_cervical_2" pos="0.0019 0 0.00087476">
              <geom name="vertebra_cervical_2_collision" class="nonself_collision_primitive" type="sphere" size="0.0072" density="300"/>
              <body name="vertebra_cervical_1" pos="0.0017775 0 0.00093507">
                <geom name="vertebra_cervical_1_collision" class="nonself_collision_primitive" type="sphere" size="0.0066" density="300"/>
                <body name="vertebra_axis" pos="0.0018823 -1.7567e-06 0.0017059">
                  <geom name="vertebra_axis_collision" class="nonself_collision_primitive" type="sphere" size="0.006" density="300"/>
                  <body name="vertebra_atlant" pos="0.0024522 1.757e-06 0.0013696">
                    <geom name="vertebra_atlant_collision" class="nonself_collision_primitive" type="sphere" size="0.0054" density="300"/>
                    <joint name="vertebra_atlant_extend" class="cervical_extend" pos="2.7406e-05 0 -0.00021153" axis="0 1 0"/>
                    <body name="skull" pos="0.025955 0 0.0017705">
                      <geom name="skull_0_collision" class="collision_primitive" type="ellipsoid" size="0.022095 0.016696 0.01" density="703.11" pos="-0.009059 0 0.00082" euler="0 0.17453 0"/>
                      <geom name="skull_0b_collision" class="collision_primitive" type="ellipsoid" size="0.022095 0.016696 0.01" density="1.4062" pos="-0.009059 0 0.00328" euler="0 0.17453 0"/>
                      <geom name="skull_F_collision" class="collision_primitive" type="ellipsoid" size="0.0071809 0.0089043 0.02" density="703.11" pos="0.014494 0 -0.00082" euler="0 1.9199 0"/>
                      <geom name="skull_Fb_collision" class="collision_primitive" type="ellipsoid" size="0.0071809 0.0089043 0.02" density="1.4062" pos="0.014494 0 0.00164" euler="0 1.9199 0"/>
                      <geom name="skull_L_collision" class="collision_primitive" type="ellipsoid" size="0.0071809 0.013357 0.014" density="703.11" pos="0.0054354 0.0045635 -0.00082" euler="0 1.9199 0"/>
                      <geom name="eye_L_collision" class="collision_primitive" type="sphere" group="1" size="0.004 0.004 0.004" rgba="0 0 0 1" pos="0.0011048 0.0128 0.0025"/>
                      
                      <site name="nose_0_kpsite" type="sphere" size=".005 .005 .005" rgba="1 0 0 1" pos=".038 0 -.004"/>  
                      <site name="ear_L_1_kpsite" type="sphere" size=".005 .005 .005" rgba=".9 .6 .7 1" pos="-.011 0.0128 0.013"/>
                      <site name="ear_R_2_kpsite" type="sphere" size=".005 .005 .005" rgba=".9 .6 .7 1" pos="-.011 -0.0128 0.013"/>
                      
                      
                      
                      
                      <geom name="skull_R_collision" class="collision_primitive" type="ellipsoid" size="0.0071809 0.013357 0.014" density="703.11" pos="0.0054354 -0.0045635 -0.00082" euler="0 1.9199 0"/>
                      <geom name="eye_R_collision" class="collision_primitive" type="sphere" group="1" size="0.004 0.004 0.004" rgba="0 0 0 1" pos="0.0011048 -0.0128 0.0025"/>
                      <geom name="skull_P0_collision" class="collision_primitive" type="box" size="0.0066286 0.006233 0.0016" density="703.11" pos="0.0018118 0 -0.00574"/>
                      <geom name="skull_P1_collision" class="collision_primitive" type="box" size="0.004419 0.004007 0.0012" density="703.11" pos="0.0063413 0 -0.00574"/>
                      <geom name="skull_P2_collision" class="collision_primitive" type="box" size="0.0011048 0.0033391 0.0008" density="703.11" pos="0.0086061 0 -0.00574"/>
                      <geom name="skull_T0_collision" class="collision_primitive" type="ellipsoid" size="0.0055238 0.0066783 0.004" density="703.11" pos="0.029895 0 -0.00656" euler="0 0.5236 0"/>
                      <geom name="skull_T1_collision" class="collision_primitive" type="ellipsoid" group="1" size="0.0022095 0.0016696 0.007" rgba="1 1 1 1" density="703.11" pos="0.028083 0.0009127 -0.0123" euler="0 0.5236 0"/>
                      <geom name="skull_T2_collision" class="collision_primitive" type="ellipsoid" group="1" size="0.0022095 0.0016696 0.007" rgba="1 1 1 1" density="703.11" pos="0.028083 -0.0009127 -0.0123" euler="0 0.5236 0"/>
                      <joint name="atlas" class="atlas" pos="-0.028436 0 0"/>
                      <site name="head" class="sensor" type="box" size="0.002 0.002 0.002"/>
                      <camera name="egocentric" fovy="80" pos="0.01 0 0.005" euler="0 -1.5708 -1.5708"/>
                      <body name="jaw" pos="0.00045295 0 -0.0164" euler="0 0.2618 0">
                        <geom name="jaw_back_collision" class="collision_primitive" type="ellipsoid" size="0.012152 0.013357 0.007" density="314.06" pos="-0.010871 0 0.00205" euler="0 0.95993 0"/>
                        <geom name="jaw_F_collision" class="collision_primitive" type="ellipsoid" size="0.0033143 0.0066783 0.012" density="314.06" pos="0.0027177 0 -0.00492" euler="0 1.8326 0"/>
                        <geom name="jaw_L_collision" class="collision_primitive" type="ellipsoid" size="0.0099429 0.0038957 0.016" density="314.06" pos="-0.0054354 0.0082143 0.00082" euler="-0.69813 2.1817 0.5236"/>
                        <geom name="jaw_R_collision" class="collision_primitive" type="ellipsoid" size="0.0099429 0.0038957 0.016" density="314.06" pos="-0.0054354 -0.0082143 0.00082" euler="0.69813 2.1817 -0.5236"/>
                        <geom name="jaw_T0_collision" class="collision_primitive" type="ellipsoid" size="0.0033143 0.0033391 0.006" density="314.06" pos="0.012683 0 -0.00574" euler="0 1.2217 0"/>
                        <geom name="jaw_T1_collision" class="collision_primitive" type="ellipsoid" group="1" size="0.0022095 0.0013357 0.007" rgba="1 1 1 1" density="314.06" pos="0.017212 0.0009127 -0.0041" euler="0 1.1345 0"/>
                        <geom name="jaw_T2_collision" class="collision_primitive" type="ellipsoid" group="1" size="0.0022095 0.0013357 0.007" rgba="1 1 1 1" density="314.06" pos="0.017212 -0.0009127 -0.0041" euler="0 1.1345 0"/>
                        <geom name="jaw_P0_collision" class="collision_primitive" type="box" size="0.0066286 0.006233 0.0016" density="314.06" pos="-0.0027177 0 0.00082" euler="0 0.95993 0"/>
                        <geom name="jaw_P1_collision" class="collision_primitive" type="box" size="0.004419 0.0048974 0.001" density="314.06" pos="0 0 -0.000984" euler="0 0.5236 0"/>
                        <geom name="jaw_P2_collision" class="collision_primitive" type="box" size="0.004419 0.004007 0.001" density="314.06" pos="0.0027177 0 -0.002296" euler="0 0.43633 0"/>
                        <geom name="jaw_P3_collision" class="collision_primitive" type="box" size="0.0033143 0.0028939 0.0006" density="314.06" pos="0.0047107 0 -0.00287" euler="0 0.2618 0"/>
                        <joint name="mandible" class="mandible" pos="-0.0185 0 0.004" axis="0 1 0"/>
                      </body>
                    </body>
                  </body>
                  <joint name="vertebra_axis_twist" class="cervical_twist" pos="9.9439e-05 0 -0.00026762" axis="0.74098 -0.00069152 0.67152"/>
                </body>
                <joint name="vertebra_cervical_1_bend" class="cervical_bend" pos="2.747e-05 0 -0.00026377" axis="-0.46557 0 0.88501"/>
              </body>
              <joint name="vertebra_cervical_2_extend" class="cervical_extend" pos="1.2952e-05 0 -0.00025387" axis="0 1 0"/>
            </body>
            <joint name="vertebra_cervical_3_twist" class="cervical_twist" pos="8.1976e-06 0 -0.00025443" axis="0.91604 0 0.4011"/>
          </body>
          <joint name="vertebra_cervical_4_bend" class="cervical_bend" pos="-1.5376e-05 4.7973e-07 -0.00027279" axis="-0.31855 0 0.9479"/>
        </body>
        <joint name="vertebra_cervical_5_extend" class="cervical_extend" pos="-0.00019346 -3.9986e-07 -0.00022969" axis="0 1 0"/>
      </body>




      <body name="scapula_L" pos="0.00656 0.00164 0.01148">

        <site name="shoulder_L_6_kpsite" type="sphere" size=".005 .005 .005" rgba=".9 .6 .7 1" pos="0.026 0.02 -.004"/>

        <joint name="scapula_L_supinate" class="scapula_supinate" pos="0 -0.005000000000000001 0" axis="-0 -0 1"/>
        <joint name="scapula_L_abduct" class="scapula_abduct" pos="0 -0.005000000000000001 -0.01" axis="1 -0 -0"/>
        <joint name="scapula_L_extend" class="scapula_extend" pos="0 0 0" axis="0.3 1 0"/>
        <site name="shoulder_L" size="0.002" pos="0.0287 0.00984 -0.02542"/>
        <body name="upper_arm_L" pos="0.0287 0.00984 -0.02542">
          <joint name="shoulder_L" class="shoulder" axis="0 1 0"/>
          <joint name="shoulder_sup_L" class="shoulder_sup" axis="0 0 -1"/>
          <site name="elbow_L" type="cylinder" size="0.0006000000000000001 0.004" pos="-0.01593120836133218 0.01035528543486592 -0.02230369170586505" zaxis="0 1 0.2"/>
          <body name="lower_arm_L" pos="-0.01593120836133218 0.01035528543486592 -0.02230369170586505">

            <site name="elbow_L_7_kpsite" type="sphere" size=".008 .008 .008" rgba=".9 .6 .7 1" pos="0 0 0"/>

            <joint name="elbow_L" class="elbow" axis="0 1 0.2"/>
            <site name="wrist_L" type="cylinder" size="0.0008 0.0034" pos="0.02160265376479308 0.01260154802946263 -0.01980243261772699" zaxis="0 1 0"/>
            <body name="hand_L" pos="0.02160265376479308 0.01260154802946263 -0.01980243261772699">
              <site name="wrist_L_8_kpsite" type="sphere" size=".005 .005 .005" rgba=".9 .6 .7 1" pos="0 0 0"/>

              <geom name="hand_L_collision" class="collision_primitive_paw" type="ellipsoid" size="0.006 0.006 0.006" density="2531.78122831" pos="0.001515873457919734 0.0007579367289598669 -0.002547620373759201" euler="0 0 0"/> 

              <body name="finger_L" pos="0.003031746915839468 0.001515873457919734 -0.008337304018558537">
                <site name="hand_L_9_kpsite" type="sphere" size=".005 .005 .005" rgba=".9 .6 .7 1" pos="0 0 0"/>
                <site name="palm_L" class="sensor" type="box" size="0.004 0.004 0.002" pos="0.00492 0.00246 -0.00164" euler="0 0 0.4886921905584123"/>
              </body>
            </body>
            <geom name="radius_L_collision" class="collision_primitive" size="0.003732165792697991 0.01591658941003555" pos="0.01150545467526729 0.006850732667129763 -0.01222632491350886" quat="0.02376493230846292 0.7917721441518218 0.4232293467931716 0.4397829234413568"/>
            <geom name="ulna_L_collision" class="collision_primitive" size="0.004390783285527048 0.01317234985658114" pos="0.006749764363547758 0.004992418652633264 -0.009489848452311813" quat="0.01282244452041863 0.7446249872782607 0.4776065607195328 0.4661128472752391"/>
          </body>
          <geom name="humerus_L_collision" class="collision_primitive" size="0.007771321151869356 0.01554264230373871" pos="-0.007743344450064287 0.005787978890072665 -0.01198335273722202" quat="0.472560999180163 0.3450082805420177 0.0007016050154913519 0.8109592444517103"/>
        </body>
        <geom name="scapula_L_collision" class="nonself_collision_primitive" type="ellipsoid" size="0.005005370825529099 0.01463182792067528 0.02431104406714439" density="513.564612303" pos="0.01757062251063465 0.008636916680112587 -0.01522952249267691" quat="0.1844194062696375 0.7692222855376651 0.4740322845517004 0.3867556738123709"/>
      </body>






      <body name="scapula_R" pos="0.00656 -0.00164 0.01148">

        <site name="shoulder_R_10_kpsite" type="sphere" size=".005 .005 .005" rgba=".9 .6 .7 1" pos="0.026 -0.02 -.004"/>

        <joint name="scapula_R_supinate" class="scapula_supinate" pos="0 0.005000000000000001 0" axis="0 0 -1"/>
        <joint name="scapula_R_abduct" class="scapula_abduct" pos="0 0.005000000000000001 -0.01" axis="-1 0 0"/>
        <joint name="scapula_R_extend" class="scapula_extend" pos="0 0 0" axis="-0.3 1 0"/>
        <site name="shoulder_R" size="0.002" pos="0.0287 -0.00984 -0.02542"/>
        <body name="upper_arm_R" pos="0.0287 -0.00984 -0.02542">
          <joint name="shoulder_R" class="shoulder" axis="0 1 0"/>
          <joint name="shoulder_sup_R" class="shoulder_sup" axis="-0 -0 1"/>
          <site name="elbow_R" type="cylinder" size="0.0006000000000000001 0.004" pos="-0.01593120836133218 -0.01035528543486592 -0.02230369170586505" zaxis="0 1 -0.2"/>
          <body name="lower_arm_R" pos="-0.01593120836133218 -0.01035528543486592 -0.02230369170586505">
            <site name="elbow_R_11_kpsite" type="sphere" size=".008 .008 .008" rgba=".9 .6 .7 1" pos="0 0 0"/>
            <joint name="elbow_R" class="elbow" axis="0 1 -0.2"/>
            <site name="wrist_R" type="cylinder" size="0.0008 0.0034" pos="0.02160265376479308 -0.01260154802946263 -0.01980243261772699" zaxis="0 1 0"/>
            <body name="hand_R" pos="0.02160265376479308 -0.01260154802946263 -0.01980243261772699">

              <site name="wrist_R_12_kpsite" type="sphere" size=".005 .005 .005" rgba=".9 .6 .7 1" pos="0 0 0"/>

          
              <geom name="hand_R_collision" class="collision_primitive_paw" type="ellipsoid" size="0.006 0.006 0.006" density="2531.78122831" pos="0.001515873457919734 -0.0007579367289598669 -0.002547620373759201" euler="0 0 0"/>
       
              <body name="finger_R" pos="0.003031746915839468 -0.001515873457919734 -0.008337304018558537">
                <site name="hand_R_13_kpsite" type="sphere" size=".005 .005 .005" rgba=".9 .6 .7 1" pos="0 0 0"/>

                <site name="palm_R" class="sensor" type="box" size="0.004 0.004 0.002" pos="0.00492 -0.00246 -0.00164" euler="0 0 -0.4886921905584123"/>
              </body>
            </body>
            <geom name="radius_R_collision" class="collision_primitive" size="0.003732165792697991 0.01591658941003555" pos="0.01150546139578159 -0.0068511746740596 -0.01222632995360402" quat="0.4397828585901176 0.423230473256099 0.7917715587074765 0.02376557635859348"/>
            <geom name="ulna_R_collision" class="collision_primitive" size="0.004390783285527048 0.01317234985658114" pos="0.006749766930753688 -0.004992858736000205 -0.009489848507155575" quat="0.4661127828257156 0.4776067795325061 0.7446248854693838 0.01282254930824632"/>
          </body>
          <geom name="humerus_R_collision" class="collision_primitive" size="0.007771321151869356 0.01554264230373871" pos="-0.007743341889514446 -0.005788347560550173 -0.01198335067124012" quat="0.8109593935310486 0.0007013948082913995 0.3450082795040448 0.4725607444157158"/>
        </body>
        <geom name="scapula_R_collision" class="nonself_collision_primitive" type="ellipsoid" size="0.005005370266735553 0.01463183127343655 0.02431103959679604" density="513.564646393" pos="0.01757062018850453 -0.008637295267367218 -0.01522952062810994" quat="0.3867556972129688 0.4740321312040688 0.7692223496423682 0.1844194839763772"/>
      </body>
    </body>



  </worldbody>

  <contact>
    <exclude name="pelvis:vertebra_C2" body1="pelvis" body2="vertebra_C2"/>
    <exclude name="pelvis:vertebra_C3" body1="pelvis" body2="vertebra_C3"/>
    <exclude name="pelvis:vertebra_C4" body1="pelvis" body2="vertebra_C4"/>
    <exclude name="vertebra_C1:vertebra_C3" body1="vertebra_C1" body2="vertebra_C3"/>
    <exclude name="vertebra_C1:vertebra_C4" body1="vertebra_C1" body2="vertebra_C4"/>
    <exclude name="vertebra_C2:vertebra_C4" body1="vertebra_C2" body2="vertebra_C4"/>
    <exclude name="vertebra_C3:vertebra_C5" body1="vertebra_C3" body2="vertebra_C5"/>
    <exclude name="vertebra_C4:vertebra_C6" body1="vertebra_C4" body2="vertebra_C6"/>
    <exclude name="vertebra_C5:vertebra_C7" body1="vertebra_C5" body2="vertebra_C7"/>
    <exclude name="vertebra_axis:skull" body1="vertebra_axis" body2="skull"/>
    <exclude name="pelvis:vertebra_C5" body1="pelvis" body2="vertebra_C5"/>
    <exclude name="pelvis:vertebra_C6" body1="pelvis" body2="vertebra_C6"/>
    <exclude name="vertebra_C2:vertebra_C5" body1="vertebra_C2" body2="vertebra_C5"/>
    <exclude name="vertebra_C3:vertebra_C6" body1="vertebra_C3" body2="vertebra_C6"/>
    <exclude name="vertebra_C4:vertebra_C7" body1="vertebra_C4" body2="vertebra_C7"/>
    <exclude name="upper_arm_L:upper_arm_R" body1="upper_arm_L" body2="upper_arm_R"/>
    <exclude name="upper_leg_L:vertebra_C1" body1="upper_leg_L" body2="vertebra_C1"/>
    <exclude name="upper_leg_L:vertebra_C2" body1="upper_leg_L" body2="vertebra_C2"/>
    <exclude name="upper_leg_R:vertebra_C1" body1="upper_leg_R" body2="vertebra_C1"/>
    <exclude name="upper_leg_R:vertebra_C2" body1="upper_leg_R" body2="vertebra_C2"/>
    <exclude name="vertebra_cervical_1:skull" body1="vertebra_cervical_1" body2="skull"/>
    <exclude name="vertebra_cervical_2:skull" body1="vertebra_cervical_2" body2="skull"/>
    <exclude name="upper_arm_L:torso" body1="upper_arm_L" body2="torso"/>
    <exclude name="upper_arm_R:torso" body1="upper_arm_R" body2="torso"/>
    <exclude name="lower_leg_L:pelvis" body1="lower_leg_L" body2="pelvis"/>
    <exclude name="lower_leg_R:pelvis" body1="lower_leg_R" body2="pelvis"/>
  </contact>

  <tendon>
    <fixed name="lumbar_extend" class="lumbar_extend">
      <joint joint="vertebra_1_extend" coef="0.60498"/>
      <joint joint="vertebra_4_extend" coef="0.39502"/>
    </fixed>
    <fixed name="lumbar_bend" class="lumbar_bend">
      <joint joint="vertebra_2_bend" coef="0.65821"/>
      <joint joint="vertebra_5_bend" coef="0.34179"/>
    </fixed>
    <fixed name="lumbar_twist" class="lumbar_twist">
      <joint joint="vertebra_3_twist" coef="0.57067"/>
      <joint joint="vertebra_6_twist" coef="0.42933"/>
    </fixed>
    <fixed name="cervical_extend" class="cervical_extend">
      <joint joint="vertebra_cervical_5_extend" coef="0.34171"/>
      <joint joint="vertebra_cervical_2_extend" coef="0.33241"/>
      <joint joint="vertebra_atlant_extend" coef="0.32588"/>
    </fixed>
    <fixed name="cervical_bend" class="cervical_bend">
      <joint joint="vertebra_cervical_4_bend" coef="0.50744"/>
      <joint joint="vertebra_cervical_1_bend" coef="0.49256"/>
    </fixed>
    <fixed name="cervical_twist" class="cervical_twist">
      <joint joint="vertebra_cervical_3_twist" coef="0.49614"/>
      <joint joint="vertebra_axis_twist" coef="0.50386"/>
    </fixed>
    <fixed name="caudal_extend" class="caudal_extend">
      <joint joint="vertebra_C1_extend" coef="0.29007"/>
      <joint joint="vertebra_C2_extend" coef="0.20767"/>
      <joint joint="vertebra_C3_extend" coef="0.15164"/>
      <joint joint="vertebra_C4_extend" coef="0.11543"/>
      <joint joint="vertebra_C5_extend" coef="0.08755"/>
      <joint joint="vertebra_C6_extend" coef="0.069256"/>
      <joint joint="vertebra_C7_extend" coef="0.055869"/>
      <joint joint="vertebra_C11_extend" coef="0.017531"/>
      <joint joint="vertebra_C15_extend" coef="0.0041442"/>
      <joint joint="vertebra_C19_extend" coef="0.00074642"/>
      <joint joint="vertebra_C23_extend" coef="8.5913e-05"/>
      <joint joint="vertebra_C27_extend" coef="1.4273e-05"/>
    </fixed>
    <fixed name="caudal_bend" class="caudal_bend">
      <joint joint="vertebra_C1_bend" coef="0.37079"/>
      <joint joint="vertebra_C2_bend" coef="0.23352"/>
      <joint joint="vertebra_C3_bend" coef="0.15089"/>
      <joint joint="vertebra_C4_bend" coef="0.10189"/>
      <joint joint="vertebra_C5_bend" coef="0.067174"/>
      <joint joint="vertebra_C6_bend" coef="0.043956"/>
      <joint joint="vertebra_C9_bend" coef="0.01882"/>
      <joint joint="vertebra_C13_bend" coef="0.0099989"/>
      <joint joint="vertebra_C17_bend" coef="0.0025264"/>
      <joint joint="vertebra_C21_bend" coef="0.00037878"/>
      <joint joint="vertebra_C25_bend" coef="4.1066e-05"/>
      <joint joint="vertebra_C29_bend" coef="1.4387e-05"/>
    </fixed>
  </tendon>

  <actuator>
    <general name="lumbar_extend" class="lumbar_extend" tendon="lumbar_extend"/>
    <general name="lumbar_bend" class="lumbar_bend" tendon="lumbar_bend"/>
    <general name="lumbar_twist" class="lumbar_twist" tendon="lumbar_twist"/>
    <general name="cervical_extend" class="cervical_extend" tendon="cervical_extend"/>
    <general name="cervical_bend" class="cervical_bend" tendon="cervical_bend"/>
    <general name="cervical_twist" class="cervical_twist" tendon="cervical_twist"/>

    <general name="caudal_extend" class="caudal_extend" tendon="caudal_extend"/>
    <general name="caudal_bend" class="caudal_bend" tendon="caudal_bend"/>
    <general name="hip_L_supinate" class="hip_supinate" joint="hip_L_supinate"/>
    <general name="hip_L_abduct" class="hip_abduct" joint="hip_L_abduct"/>
    <general name="hip_L_extend" class="hip_extend" joint="hip_L_extend"/>
    <general name="knee_L" class="knee" joint="knee_L"/>
    <general name="ankle_L" class="ankle" joint="ankle_L"/>
    <general name="hip_R_supinate" class="hip_supinate" joint="hip_R_supinate"/>
    <general name="hip_R_abduct" class="hip_abduct" joint="hip_R_abduct"/>
    <general name="hip_R_extend" class="hip_extend" joint="hip_R_extend"/>
    <general name="knee_R" class="knee" joint="knee_R"/>
    <general name="ankle_R" class="ankle" joint="ankle_R"/>

    <general name="atlas" class="atlas" joint="atlas"/>
    <general name="mandible" class="mandible" joint="mandible"/>
    <general name="scapula_L_supinate" class="scapula_supinate" joint="scapula_L_supinate"/>
    <general name="scapula_L_abduct" class="scapula_abduct" joint="scapula_L_abduct"/>
    <general name="scapula_L_extend" class="scapula_extend" joint="scapula_L_extend"/>
    <general name="shoulder_L" class="shoulder" joint="shoulder_L"/>
    <general name="shoulder_sup_L" class="shoulder_sup" joint="shoulder_sup_L"/>
    <general name="elbow_L" class="elbow" joint="elbow_L"/>
    <general name="scapula_R_supinate" class="scapula_supinate" joint="scapula_R_supinate"/>
    <general name="scapula_R_abduct" class="scapula_abduct" joint="scapula_R_abduct"/>
    <general name="scapula_R_extend" class="scapula_extend" joint="scapula_R_extend"/>
    <general name="shoulder_R" class="shoulder" joint="shoulder_R"/>
    <general name="shoulder_sup_R" class="shoulder_sup" joint="shoulder_sup_R"/>
    <general name="elbow_R" class="elbow" joint="elbow_R"/>

  </actuator>

  <sensor>
    <accelerometer name="accelerometer" site="head"/>
    <velocimeter name="velocimeter" site="head"/>
    <gyro name="gyro" site="head"/>
    <touch name="palm_L" site="palm_L"/>
    <touch name="palm_R" site="palm_R"/>
    <touch name="sole_L" site="sole_L"/>
    <touch name="sole_R" site="sole_R"/>
    <subtreelinvel name="torso" body="torso"/>
  </sensor>

</mujoco>
